<mujoco>

    <worldbody>
        <body name="base" pos=".25 .25 .15" euler="0 90 0">
            <joint type="slide" axis="0 0 1" armature="0.00001"/>
            <joint type="slide" axis="1 0 0" armature="0.00001"/>
            <joint type="slide" axis="0 1 0" armature="0.00001"/>
            <joint type="hinge" axis="0 1 0" armature="0.00001"/>
            <joint type="hinge" axis="1 0 0" armature="0.00001"/>
            <joint type="hinge" axis="0 0 1" armature="0.00001"/>
            <geom type="capsule" size=".03" fromto="0 0 0 .1 0 0" 
            mass=".05" rgba="0 1 1 .2"/>
            <body name="wing_1_1" pos="0 .02 0" gravcomp="1">
                <joint name="AoA" axis="0 1 0" armature="1"/>
                <joint name="sweep_angle" axis="0 0 1" armature="1"/>
                <joint name="flap_angle" axis="1 0 0" armature="1"/>
                <geom type="box" size=".055 .035 .0005" pos=".055 .035 0" 
                    mass=".001" contype="0" conaffinity="0" rgba="0 1 1 1"/>
                <body name="wing_1_2" pos="0 .07 0" gravcomp="1">
                    <geom type="box" size=".055 .035 .0005" pos=".055 .035 .0005"
                        mass=".001" contype="0" conaffinity="0" rgba="0 1 1 1"/>
                    <body name="wing_1_3" pos="0 .07 0" gravcomp="1">
                        <geom type="box" size=".055 .035 .0005" pos=".055 .035 .0005"
                            mass=".001" contype="0" conaffinity="0" rgba="0 1 1 1"/>
                        <body name="wing_1_4" pos="0 .07 0" euler="0 0 15" gravcomp="1">
                            <geom type="box" size=".0535 .015 .0005" pos=".0535 -.015 .0005"
                                mass=".0002" contype="0" conaffinity="0" rgba="0 1 1 1"/>
                            <body name="wing_1_5" pos="0 0 0" euler="0 0 17" gravcomp="1">
                                <geom type="box" size=".0535 .015 .0005" pos=".0535 -.015 .0005"
                                    mass=".0002" contype="0" conaffinity="0" rgba="0 1 1 1"/>
                                <body name="wing_1_6" pos="0 0 0" euler="0 0 17" gravcomp="1">
                                    <geom type="box" size=".056 .015 .0005" pos=".056 -.015 .0005"
                                        mass=".0002" contype="0" conaffinity="0" rgba="0 1 1 1"/>
                                    <body name="wing_1_7" pos="0 0 0" euler="0 0 16" gravcomp="1">
                                        <geom type="box" size=".0635 .015 .0005" pos=".0635 -.015 .0005"
                                            mass=".0002" contype="0" conaffinity="0" rgba="0 1 1 1"/>
                                        <body name="wing_1_8" pos="0 0 0" euler="0 0 14" gravcomp="1">
                                            <geom type="box" size=".07 .015 .0005" pos=".07 -.015 .0005"
                                                mass=".0002" contype="0" conaffinity="0" rgba="0 1 1 1"/>
                                        </body>
                                    </body>
                                </body>
                            </body>
                        </body>
                    </body>
                </body>
            </body>

            <body name="wing_2_1" pos="0 -.02 0" gravcomp="1">
                <joint name="AoA2" axis="0 1 0"  armature="1"/>
                <joint name="sweep_angle2" axis="0 0 1"  armature="1"/>
                <joint name="flap_angle2" axis="1 0 0"  armature="1"/>
                <geom type="box" size=".055 .035 .0005" pos=".055 -.035 0" 
                    mass=".001" contype="0" conaffinity="0" rgba="0 1 1 1"/>
                <body name="wing_2_2" pos="0 -.07 0" gravcomp="1">
                    <geom type="box" size=".055 .035 .0005" pos=".055 -.035 .0005"
                        mass=".001" contype="0" conaffinity="0" rgba="0 1 1 1"/>
                    <body name="wing_2_3" pos="0 -.07 0" gravcomp="1">
                        <geom type="box" size=".055 .035 .0005" pos=".055 -.035 .0005"
                            mass=".001" contype="0" conaffinity="0" rgba="0 1 1 1"/>
                        <body name="wing_2_4" pos="0 -.07 0" euler="0 0 -15" gravcomp="1">
                            <geom type="box" size=".0535 .015 .0005" pos=".0535 .015 .0005"
                                mass=".0002" contype="0" conaffinity="0" rgba="0 1 1 1"/>
                            <body name="wing_2_5" pos="0 0 0" euler="0 0 -17" gravcomp="1">
                                <geom type="box" size=".0535 .015 .0005" pos=".0535 .015 .0005"
                                    mass=".0002" contype="0" conaffinity="0" rgba="0 1 1 1"/>
                                <body name="wing_2_6" pos="0 0 0" euler="0 0 -17" gravcomp="1">
                                    <geom type="box" size=".056 .015 .0005" pos=".056 .015 .0005"
                                        mass=".0002" contype="0" conaffinity="0" rgba="0 1 1 1"/>
                                    <body name="wing_2_7" pos="0 0 0" euler="0 0 -16" gravcomp="1">
                                        <geom type="box" size=".0635 .015 .0005" pos=".0635 .015 .0005"
                                            mass=".0002" contype="0" conaffinity="0" rgba="0 1 1 1"/>
                                        <body name="wing_2_8" pos="0 0 0" euler="0 0 -14" gravcomp="1">
                                            <geom type="box" size=".07 .015 .0005" pos=".07 .015 .0005"
                                                mass=".0002" contype="0" conaffinity="0" rgba="0 1 1 1"/>
                                        </body>
                                    </body>
                                </body>
                            </body>
                        </body>
                    </body>
                </body>
            </body>

            <body name="tail" pos=".15 0 0">
                <joint name="tail_pitch" axis="0 1 0"  armature="1"/>
                <joint name="tail_roll" axis="1 0 0"  armature="1"/>
                <geom type="box" size=".07 .015 .0005" pos=".07 0 .0005" 
                    contype="0" conaffinity="0" mass=".0005" rgba="0 1 0 1"/>
                <body name="tail_1" euler="0 0 10">
                    <geom type="box" size=".07 .015 .0005" pos=".07 0 .0005" 
                        contype="0" conaffinity="0" mass=".0005" rgba="0 1 0 1"/>
                    <body name="tail_2" euler="0 0 10">
                        <geom type="box" size=".07 .015 .0005" pos=".07 0 .0005" 
                            contype="0" conaffinity="0" mass=".0005" rgba="0 1 0 1"/>
                        <body name="tail_3" euler="0 0 10">
                            <geom type="box" size=".07 .015 .0005" pos=".07 0 .0005" 
                                contype="0" conaffinity="0" mass=".0005" rgba="0 1 0 1"/>
                            <body name="tail_4" euler="0 0 10">
                                <geom type="box" size=".07 .015 .0005" pos=".07 0 .0005" 
                                    contype="0" conaffinity="0" mass=".0005" rgba="0 1 0 1"/>
                                <body name="tail_5" euler="0 0 10">
                                    <geom type="box" size=".07 .015 .0005" pos=".07 0 .0005" 
                                        contype="0" conaffinity="0" mass=".0005" rgba="0 1 0 1"/>
                                    <body name="tail_6" euler="0 0 10">
                                        <geom type="box" size=".07 .015 .0005" pos=".07 0 .0005" 
                                            contype="0" conaffinity="0" mass=".0005" rgba="0 1 0 1"/>
                                        <body name="tail_7" euler="0 0 10">
                                            <geom type="box" size=".07 .015 .0005" pos=".07 0 .0005" 
                                                contype="0" conaffinity="0" mass=".0005" rgba="0 1 0 1"/>
                                            <body name="tail_8" euler="0 0 10">
                                                <geom type="box" size=".07 .015 .0005" pos=".07 0 .0005" 
                                                    contype="0" conaffinity="0" mass=".0005" rgba="0 1 0 1"/>
                                            </body>
                                        </body>
                                    </body>
                                </body>
                            </body>
                        </body>
                    </body>
                </body>

                <body name="tail_9" euler="0 0 -10">
                    <geom type="box" size=".07 .015 .0005" pos=".07 0 .0005" 
                        contype="0" conaffinity="0" mass=".0005" rgba="0 1 0 1"/>
                    <body name="tail_10" euler="0 0 -10">
                        <geom type="box" size=".07 .015 .0005" pos=".07 0 .0005" 
                            contype="0" conaffinity="0" mass=".0005" rgba="0 1 0 1"/>
                        <body name="tail_11" euler="0 0 -10">
                            <geom type="box" size=".07 .015 .0005" pos=".07 0 .0005" 
                                contype="0" conaffinity="0" mass=".0005" rgba="0 1 0 1"/>
                            <body name="tail_12" euler="0 0 -10">
                                <geom type="box" size=".07 .015 .0005" pos=".07 0 .0005" 
                                    contype="0" conaffinity="0" mass=".0005" rgba="0 1 0 1"/>
                                <body name="tail_13" euler="0 0 -10">
                                    <geom type="box" size=".07 .015 .0005" pos=".07 0 .0005" 
                                        contype="0" conaffinity="0" mass=".0005" rgba="0 1 0 1"/>
                                    <body name="tail_14" euler="0 0 -10">
                                        <geom type="box" size=".07 .015 .0005" pos=".07 0 .0005" 
                                            contype="0" conaffinity="0" mass=".0005" rgba="0 1 0 1"/>
                                        <body name="tail_15" euler="0 0 -10">
                                            <geom type="box" size=".07 .015 .0005" pos=".07 0 .0005" 
                                                contype="0" conaffinity="0" mass=".0005" rgba="0 1 0 1"/>
                                            <body name="tail_16" euler="0 0 -10">
                                                <geom type="box" size=".07 .015 .0005" pos=".07 0 .0005" 
                                                    contype="0" conaffinity="0" mass=".0005" rgba="0 1 0 1"/>
                                            </body>
                                        </body>
                                    </body>
                                </body>
                            </body>
                        </body>
                    </body>
                </body>
            </body>
        </body>
        <body name="red_marker" mocap="true" >
            <geom type="sphere" size="0.05" rgba="1 0 0 0.95"/>
        </body>
    </worldbody>

    <actuator>
        <position name="AoA" joint="AoA" kp="1000" dampratio=".5" ctrlrange="-.7 .7"/>
        <position name="sweep_angle" joint="sweep_angle" kp="1000" dampratio=".5" ctrlrange="-.7 .7"/>
        <position name="flap_angle" joint="flap_angle" kp="1000" dampratio=".5" ctrlrange="-1.5 1.5"/>
        <position name="AoA2" joint="AoA2" kp="1000" dampratio=".5" ctrlrange="-.7 .7"/>
        <position name="sweep_angle2" joint="sweep_angle2" kp="1000" dampratio=".5" ctrlrange="-.7 .7"/>
        <position name="flap_angle2" joint="flap_angle2" kp="1000" dampratio=".5" ctrlrange="-1.5 1.5"/>
        <position name="tail_pitch" joint="tail_pitch" kp="1000" dampratio="1" ctrlrange="-1.5 1.5"/>
        <position name="tail_roll" joint="tail_roll" kp="1000" dampratio="1" ctrlrange="-1 1"/>
    </actuator>

</mujoco>